Workbook

Sheet Requests
A1: Request ID | B1: Title | C1: Status | D1: Status Code | E1: Embargo Status | F1: Agency ID | G1: Agency Name | H1: Jurisdiction | I1: User ID | J1: Tracking ID | K1: Price | L1: Date Submitted | M1: Date Updated | N1: Date Done | O1: Days Open | P1: Days Since Update | Q1: MuckRock URL | R1: Tags | S1: Entity | T1: Kind | U1: Counterpart | V1: Auto Score | W1: Manual Score | X1: Effective | Y1: Exclude | Z1: Notes
A2: 200204 | B2: AI chat logs (Belmont Clerk) | C2: No Responsive Documents | D2: no_docs | E2: Public | F2: 43740 | G2: Belmont Clerk | H2: Belmont | I2: 114503 | K2: 0 | L2: 2025-12-18 17:11 | M2: 2026-01-09 20:29 | N2: 2026-01-09 20:29 | O2: 17 | Q2: https://www.muckrock.com/foi/belmont-3816/ai-chat-logs-belmont-clerk-200204/ | R2: transparent-nh | S2: Belmont | T2: town | U2: Shaker Regional School District/SAU80 | V2: 0 | X2: =IF(Y2=TRUE,"",IF(ISNUMBER(W2),W2,V2)) | Y2: FALSE
A3: 200201 | B3: AI chat logs (Berlin Clerk) | C3: No Responsive Documents | D3: no_docs | E3: Public | F3: 43743 | G3: Berlin Clerk | H3: Berlin | I3: 114503 | K3: 0 | L3: 2025-12-18 17:11 | M3: 2025-12-22 14:59 | N3: 2025-12-22 14:59 | O3: 3 | Q3: https://www.muckrock.com/foi/berlin-3819/ai-chat-logs-berlin-clerk-200201/ | R3: transparent-nh | S3: Berlin | T3: town | U3: Berlin School District/SAU 3 | V3: 0 | X3: =IF(Y3=TRUE,"",IF(ISNUMBER(W3),W3,V3)) | Y3: FALSE
A4: 200208 | B4: AI chat logs (Bow Clerk) | C4: No Responsive Documents | D4: no_docs | E4: Public | F4: 43753 | G4: Bow Clerk | H4: Bow | I4: 114503 | K4: 0 | L4: 2025-12-18 17:11 | M4: 2026-06-02 19:19 | N4: 2026-06-02 19:19 | O4: 119 | Q4: https://www.muckrock.com/foi/bow-3822/ai-chat-logs-bow-clerk-200208/ | R4: transparent-nh | S4: Bow | T4: town | U4: Bow School District/SAU67 | V4: 0 | X4: =IF(Y4=TRUE,"",IF(ISNUMBER(W4),W4,V4)) | Y4: FALSE
A5: 200200 | B5: AI chat logs (City Clerk) | C5: Awaiting Acknowledgement | D5: ack | E5: Public | F5: 17082 | G5: City Clerk | H5: Dover | I5: 114503 | K5: 0 | L5: 2025-12-18 17:11 | M5: 2026-07-15 05:00 | O5: 153 | P5: 4 | Q5: https://www.muckrock.com/foi/dover-3855/ai-chat-logs-city-clerk-200200/ | R5: transparent-nh | S5: Dover | T5: town | U5: Dover School District/SAU11 | V5: -5 | X5: =IF(Y5=TRUE,"",IF(ISNUMBER(W5),W5,V5)) | Y5: FALSE
A6: 200193 | B6: AI chat logs (City Clerk) | C6: Rejected | D6: rejected | E6: Public | F6: 17084 | G6: City Clerk | H6: Lebanon | I6: 114503 | K6: 0 | L6: 2025-12-18 17:11 | M6: 2025-12-22 21:48 | N6: 2025-12-22 21:48 | O6: 3 | Q6: https://www.muckrock.com/foi/lebanon-3917/ai-chat-logs-city-clerk-200193/ | R6: transparent-nh | S6: Lebanon | T6: town | U6: Lebanon School District/SAU88 | V6: -4 | X6: =IF(Y6=TRUE,"",IF(ISNUMBER(W6),W6,V6)) | Y6: FALSE
A7: 200197 | B7: AI chat logs (City Clerk's Office) | C7: No Responsive Documents | D7: no_docs | E7: Public | F7: 4246 | G7: City Clerk's Office | H7: Keene | I7: 114503 | J7: RTK-2025-133 | K7: 0 | L7: 2025-12-18 17:11 | M7: 2026-01-19 17:23 | N7: 2026-01-19 17:23 | O7: 23 | Q7: https://www.muckrock.com/foi/keene-3910/ai-chat-logs-city-clerks-office-200197/ | R7: transparent-nh | S7: Keene | T7: town | U7: Keene School District/SAU29 | V7: 0 | X7: =IF(Y7=TRUE,"",IF(ISNUMBER(W7),W7,V7)) | Y7: FALSE
A8: 200195 | B8: AI chat logs (Claremont Clerk) | C8: No Responsive Documents | D8: no_docs | E8: Public | F8: 43744 | G8: Claremont Clerk | H8: Claremont | I8: 114503 | K8: 0 | L8: 2025-12-18 17:11 | M8: 2026-06-15 13:09 | N8: 2026-06-15 13:09 | O8: 128 | Q8: https://www.muckrock.com/foi/claremont-3840/ai-chat-logs-claremont-clerk-200195/ | R8: transparent-nh, nh-citizen | S8: Claremont | T8: town | U8: Claremont School District/SAU6 | V8: 0 | X8: =IF(Y8=TRUE,"",IF(ISNUMBER(W8),W8,V8)) | Y8: FALSE
A9: 200199 | B9: AI chat logs (Concord City Clerk) | C9: No Responsive Documents | D9: no_docs | E9: Public | F9: 11759 | G9: Concord City Clerk | H9: Concord | I9: 114503 | K9: 0.25 | L9: 2025-12-18 17:11 | M9: 2026-02-17 16:20 | N9: 2026-02-17 16:20 | O9: 44 | Q9: https://www.muckrock.com/foi/concord-3844/ai-chat-logs-concord-city-clerk-200199/ | R9: transparent-nh, nh-citizen | S9: Concord | T9: town | U9: Concord School District/SAU8 | V9: 0 | X9: =IF(Y9=TRUE,"",IF(ISNUMBER(W9),W9,V9)) | Y9: FALSE
A10: 200206 | B10: AI chat logs (Derry Clerk) | C10: No Responsive Documents | D10: no_docs | E10: Public | F10: 43755 | G10: Derry Clerk | H10: Derry | I10: 114503 | K10: 0 | L10: 2025-12-18 17:11 | M10: 2025-12-22 21:11 | N10: 2025-12-22 21:11 | O10: 3 | Q10: https://www.muckrock.com/foi/derry-3853/ai-chat-logs-derry-clerk-200206/ | R10: transparent-nh | S10: Derry | T10: town | U10: Derry Cooperative School District/SAU10 | V10: 0 | X10: =IF(Y10=TRUE,"",IF(ISNUMBER(W10),W10,V10)) | Y10: FALSE
A11: 211332 | B11: AI chat logs (Franklin Clerk) | C11: Partially Completed | D11: partial | E11: Public | F11: 43745 | G11: Franklin Clerk | H11: Franklin | I11: 23852 | K11: 16.04 | L11: 2026-05-15 12:31 | M11: 2026-06-03 21:18 | O11: 47 | P11: 34 | Q11: https://www.muckrock.com/foi/franklin-3874/ai-chat-logs-franklin-clerk-211332/ | R11: transparent-nh, nh-inperson | S11: Franklin | T11: town | U11: Franklin School District/SAU18 | X11: =IF(Y11=TRUE,"",IF(ISNUMBER(W11),W11,V11)) | Y11: FALSE
A12: 200209 | B12: AI chat logs (Gorham Clerk) | C12: No Responsive Documents | D12: no_docs | E12: Public | F12: 43752 | G12: Gorham Clerk | H12: Gorham | I12: 114503 | K12: 0 | L12: 2025-12-18 17:11 | M12: 2025-12-24 13:42 | N12: 2025-12-24 13:42 | O12: 5 | Q12: https://www.muckrock.com/foi/gorham-3881/ai-chat-logs-gorham-clerk-200209/ | R12: transparent-nh | S12: Gorham | T12: town | U12: Gorham School District/SAU20 | V12: 0 | X12: =IF(Y12=TRUE,"",IF(ISNUMBER(W12),W12,V12)) | Y12: FALSE
A13: 200210 | B13: AI chat logs (Hanover Clerk) | C13: No Responsive Documents | D13: no_docs | E13: Public | F13: 43751 | G13: Hanover Clerk | H13: Hanover | I13: 114503 | K13: 0 | L13: 2025-12-18 17:11 | M13: 2025-12-23 14:35 | N13: 2025-12-23 14:35 | O13: 4 | Q13: https://www.muckrock.com/foi/hanover-3893/ai-chat-logs-hanover-clerk-200210/ | R13: transparent-nh | S13: Hanover | T13: town | U13: Interstate School District/SAU70 | V13: 0 | X13: =IF(Y13=TRUE,"",IF(ISNUMBER(W13),W13,V13)) | Y13: FALSE
A14: 200207 | B14: AI chat logs (Hopkinton Clerk) | C14: No Responsive Documents | D14: no_docs | E14: Public | F14: 43754 | G14: Hopkinton Clerk | H14: Hopkinton | I14: 114503 | K14: 0 | L14: 2025-12-18 17:11 | M14: 2025-12-31 16:27 | N14: 2025-12-31 16:27 | O14: 10 | Q14: https://www.muckrock.com/foi/hopkinton-3905/ai-chat-logs-hopkinton-clerk-200207/ | R14: transparent-nh | S14: Hopkinton | T14: town | U14: Hopkinton School District/SAU66 | V14: 0 | X14: =IF(Y14=TRUE,"",IF(ISNUMBER(W14),W14,V14)) | Y14: FALSE
A15: 200194 | B15: AI chat logs (Laconia Clerk) | C15: No Responsive Documents | D15: no_docs | E15: Public | F15: 43746 | G15: Laconia Clerk | H15: Laconia | I15: 114503 | K15: 0 | L15: 2025-12-18 17:11 | M15: 2025-12-22 20:56 | N15: 2025-12-22 20:56 | O15: 3 | Q15: https://www.muckrock.com/foi/laconia-3913/ai-chat-logs-laconia-clerk-200194/ | R15: transparent-nh | S15: Laconia | T15: town | U15: Laconia School District/SAU30 | V15: 0 | X15: =IF(Y15=TRUE,"",IF(ISNUMBER(W15),W15,V15)) | Y15: FALSE
A16: 200198 | B16: AI chat logs (Manchester City Clerk) | C16: No Responsive Documents | D16: no_docs | E16: Public | F16: 8901 | G16: Manchester City Clerk | H16: Manchester | I16: 114503 | K16: 0 | L16: 2025-12-18 17:11 | M16: 2026-02-04 21:45 | N16: 2026-02-04 21:45 | O16: 35 | Q16: https://www.muckrock.com/foi/manchester-3931/ai-chat-logs-manchester-city-clerk-200198/ | R16: transparent-nh | S16: Manchester | T16: town | U16: Manchester School District/SAU37 | V16: 0 | X16: =IF(Y16=TRUE,"",IF(ISNUMBER(W16),W16,V16)) | Y16: FALSE
A17: 200192 | B17: AI chat logs (Nashua City Clerk) | C17: No Responsive Documents | D17: no_docs | E17: Public | F17: 11758 | G17: Nashua City Clerk | H17: Nashua | I17: 114503 | K17: 0 | L17: 2025-12-18 17:11 | M17: 2026-01-06 16:51 | N17: 2026-01-06 16:51 | O17: 14 | Q17: https://www.muckrock.com/foi/nashua-3944/ai-chat-logs-nashua-city-clerk-200192/ | R17: transparent-nh | S17: Nashua | T17: town | U17: Nashua School District/SAU 42 | V17: 0 | X17: =IF(Y17=TRUE,"",IF(ISNUMBER(W17),W17,V17)) | Y17: FALSE
A18: 200211 | B18: AI chat logs (Peterborough Clerk) | C18: No Responsive Documents | D18: no_docs | E18: Public | F18: 43750 | G18: Peterborough Clerk | H18: Peterborough | I18: 114503 | K18: 0 | L18: 2025-12-18 17:11 | M18: 2026-01-12 15:38 | N18: 2026-01-12 15:38 | O18: 18 | Q18: https://www.muckrock.com/foi/peterborough-3968/ai-chat-logs-peterborough-clerk-200211/ | R18: transparent-nh | S18: Peterborough | T18: town | U18: Contoocook Valley School District/SAU1 | V18: 0 | X18: =IF(Y18=TRUE,"",IF(ISNUMBER(W18),W18,V18)) | Y18: FALSE
A19: 200196 | B19: AI chat logs (Portsmouth Clerk) | C19: Partially Completed | D19: partial | E19: Public | F19: 43676 | G19: Portsmouth Clerk | H19: Portsmouth | I19: 114503 | J19: RTK-2025-0000165 | K19: 8.5 | L19: 2025-12-18 17:11 | M19: 2026-02-17 22:19 | N19: 2026-01-06 21:46 | O19: 14 | Q19: https://www.muckrock.com/foi/portsmouth-3975/ai-chat-logs-portsmouth-clerk-200196/ | R19: transparent-nh, nh-inperson | S19: Portsmouth | T19: town | U19: Portsmouth School District/SAU52 | X19: =IF(Y19=TRUE,"",IF(ISNUMBER(W19),W19,V19)) | Y19: FALSE
A20: 200191 | B20: AI chat logs (Rochester Clerk) | C20: No Responsive Documents | D20: no_docs | E20: Public | F20: 43749 | G20: Rochester Clerk | H20: Rochester | I20: 114503 | K20: 0 | L20: 2025-12-18 17:11 | M20: 2025-12-23 18:51 | N20: 2025-12-23 18:51 | O20: 4 | Q20: https://www.muckrock.com/foi/rochester-3980/ai-chat-logs-rochester-clerk-200191/ | R20: transparent-nh, nh-citizen | S20: Rochester | T20: town | U20: Rochester School District/SAU54 | V20: 0 | X20: =IF(Y20=TRUE,"",IF(ISNUMBER(W20),W20,V20)) | Y20: FALSE
A21: 200203 | B21: AI chat logs (Salem Clerk) | C21: No Responsive Documents | D21: no_docs | E21: Public | F21: 43741 | G21: Salem Clerk | H21: Salem | I21: 114503 | K21: 0 | L21: 2025-12-18 17:11 | M21: 2026-05-29 19:08 | N21: 2026-05-29 19:08 | O21: 117 | Q21: https://www.muckrock.com/foi/salem-3985/ai-chat-logs-salem-clerk-200203/ | R21: transparent-nh, nh-citizen | S21: Salem | T21: town | U21: Salem School District/SAU57 | V21: 0 | X21: =IF(Y21=TRUE,"",IF(ISNUMBER(W21),W21,V21)) | Y21: FALSE
A22: 200205 | B22: AI chat logs (Somersworth Clerk) | C22: No Responsive Documents | D22: no_docs | E22: Public | F22: 43739 | G22: Somersworth Clerk | H22: Somersworth | I22: 114503 | K22: 0 | L22: 2025-12-18 17:11 | M22: 2026-01-12 13:36 | N22: 2026-01-12 13:36 | O22: 18 | Q22: https://www.muckrock.com/foi/somersworth-3993/ai-chat-logs-somersworth-clerk-200205/ | R22: transparent-nh | S22: Somersworth | T22: town | U22: Somersworth School District/SAU56 | V22: 0 | X22: =IF(Y22=TRUE,"",IF(ISNUMBER(W22),W22,V22)) | Y22: FALSE
A23: 211333 | B23: AI chat logs (Town Of Durham) | C23: Rejected | D23: rejected | E23: Public | F23: 45905 | G23: Town Of Durham | H23: Durham | I23: 23852 | K23: 0 | L23: 2026-05-15 12:31 | M23: 2026-05-20 16:33 | N23: 2026-05-20 16:33 | O23: 4 | Q23: https://www.muckrock.com/foi/durham-3859/ai-chat-logs-town-of-durham-211333/ | R23: transparent-nh | S23: Durham | T23: town | U23: Oyster River Cooperative School District/SAU5 | V23: -4 | X23: =IF(Y23=TRUE,"",IF(ISNUMBER(W23),W23,V23)) | Y23: FALSE
A24: 200202 | B24: AI chat logs (Troy Clerk) | C24: No Responsive Documents | D24: no_docs | E24: Public | F24: 43742 | G24: Troy Clerk | H24: Troy | I24: 114503 | K24: 0 | L24: 2025-12-18 17:11 | M24: 2026-05-21 20:01 | N24: 2026-05-21 20:01 | O24: 111 | Q24: https://www.muckrock.com/foi/troy-4012/ai-chat-logs-troy-clerk-200202/ | S24: Troy | T24: town | U24: Monadnock Regional School District/SAU93 | V24: 0 | X24: =IF(Y24=TRUE,"",IF(ISNUMBER(W24),W24,V24)) | Y24: FALSE
A25: 200173 | B25: AI policy (Belmont Clerk) | C25: No Responsive Documents | D25: no_docs | E25: Public | F25: 43740 | G25: Belmont Clerk | H25: Belmont | I25: 114503 | K25: 0 | L25: 2025-12-18 16:38 | M25: 2025-12-22 12:58 | N25: 2025-12-22 12:58 | O25: 3 | Q25: https://www.muckrock.com/foi/belmont-3816/ai-policy-belmont-clerk-200173/ | R25: transparent-nh | S25: Belmont | T25: town | U25: Shaker Regional School District/SAU80 | V25: 0 | X25: =IF(Y25=TRUE,"",IF(ISNUMBER(W25),W25,V25)) | Y25: FALSE
A26: 200170 | B26: AI policy (Berlin Clerk) | C26: No Responsive Documents | D26: no_docs | E26: Public | F26: 43743 | G26: Berlin Clerk | H26: Berlin | I26: 114503 | K26: 0 | L26: 2025-12-18 16:38 | M26: 2025-12-22 14:58 | N26: 2025-12-22 14:58 | O26: 3 | Q26: https://www.muckrock.com/foi/berlin-3819/ai-policy-berlin-clerk-200170/ | R26: transparent-nh | S26: Berlin | T26: town | U26: Berlin School District/SAU 3 | V26: 0 | X26: =IF(Y26=TRUE,"",IF(ISNUMBER(W26),W26,V26)) | Y26: FALSE
A27: 200166 | B27: AI policy (Bow Clerk) | C27: No Responsive Documents | D27: no_docs | E27: Public | F27: 43753 | G27: Bow Clerk | H27: Bow | I27: 114503 | K27: 0 | L27: 2025-12-18 16:38 | M27: 2026-04-24 21:10 | N27: 2026-04-24 21:10 | O27: 92 | Q27: https://www.muckrock.com/foi/bow-3822/ai-policy-bow-clerk-200166/ | R27: transparent-nh | S27: Bow | T27: town | U27: Bow School District/SAU67 | V27: 0 | X27: =IF(Y27=TRUE,"",IF(ISNUMBER(W27),W27,V27)) | Y27: FALSE
A28: 200157 | B28: AI policy (City Clerk) | C28: Awaiting Acknowledgement | D28: ack | E28: Public | F28: 17082 | G28: City Clerk | H28: Dover | I28: 114503 | K28: 0 | L28: 2025-12-18 16:32 | M28: 2026-07-15 05:00 | O28: 153 | P28: 4 | Q28: https://www.muckrock.com/foi/dover-3855/ai-policy-city-clerk-200157/ | R28: transparent-nh | S28: Dover | T28: town | U28: Dover School District/SAU11 | V28: -5 | X28: =IF(Y28=TRUE,"",IF(ISNUMBER(W28),W28,V28)) | Y28: FALSE
A29: 200154 | B29: AI policy (City Clerk) | C29: Completed | D29: done | E29: Public | F29: 17084 | G29: City Clerk | H29: Lebanon | I29: 114503 | K29: 0 | L29: 2025-12-18 16:32 | M29: 2025-12-22 17:26 | N29: 2025-12-22 17:26 | O29: 3 | Q29: https://www.muckrock.com/foi/lebanon-3917/ai-policy-city-clerk-200154/ | R29: transparent-nh | S29: Lebanon | T29: town | U29: Lebanon School District/SAU88 | V29: 5 | X29: =IF(Y29=TRUE,"",IF(ISNUMBER(W29),W29,V29)) | Y29: FALSE
A30: 200156 | B30: AI policy (City Clerk's Office) | C30: Completed | D30: done | E30: Public | F30: 4246 | G30: City Clerk's Office | H30: Keene | I30: 114503 | J30: RTK-2025-134 | K30: 0 | L30: 2025-12-18 16:32 | M30: 2026-02-08 20:12 | N30: 2026-02-08 20:12 | O30: 37 | Q30: https://www.muckrock.com/foi/keene-3910/ai-policy-city-clerks-office-200156/ | R30: transparent-nh | S30: Keene | T30: town | U30: Keene School District/SAU29 | V30: 4 | X30: =IF(Y30=TRUE,"",IF(ISNUMBER(W30),W30,V30)) | Y30: FALSE
A31: 200160 | B31: AI policy (Claremont Clerk) | C31: No Responsive Documents | D31: no_docs | E31: Public | F31: 43744 | G31: Claremont Clerk | H31: Claremont | I31: 114503 | K31: 0 | L31: 2025-12-18 16:32 | M31: 2026-06-15 16:09 | N31: 2026-06-15 16:09 | O31: 128 | Q31: https://www.muckrock.com/foi/claremont-3840/ai-policy-claremont-clerk-200160/ | R31: transparent-nh, nh-citizen | S31: Claremont | T31: town | U31: Claremont School District/SAU6 | V31: 0 | X31: =IF(Y31=TRUE,"",IF(ISNUMBER(W31),W31,V31)) | Y31: FALSE
A32: 200158 | B32: AI policy (Concord City Clerk) | C32: No Responsive Documents | D32: no_docs | E32: Public | F32: 11759 | G32: Concord City Clerk | H32: Concord | I32: 114503 | K32: 0.25 | L32: 2025-12-18 16:32 | M32: 2026-02-17 16:21 | N32: 2026-02-17 16:21 | O32: 44 | Q32: https://www.muckrock.com/foi/concord-3844/ai-policy-concord-city-clerk-200158/ | R32: transparent-nh, nh-citizen | S32: Concord | T32: town | U32: Concord School District/SAU8 | V32: 0 | X32: =IF(Y32=TRUE,"",IF(ISNUMBER(W32),W32,V32)) | Y32: FALSE
A33: 200164 | B33: AI policy (Derry Clerk) | C33: No Responsive Documents | D33: no_docs | E33: Public | F33: 43755 | G33: Derry Clerk | H33: Derry | I33: 114503 | K33: 0 | L33: 2025-12-18 16:38 | M33: 2025-12-22 21:08 | N33: 2025-12-22 21:08 | O33: 3 | Q33: https://www.muckrock.com/foi/derry-3853/ai-policy-derry-clerk-200164/ | R33: transparent-nh | S33: Derry | T33: town | U33: Derry Cooperative School District/SAU10 | V33: 0 | X33: =IF(Y33=TRUE,"",IF(ISNUMBER(W33),W33,V33)) | Y33: FALSE
A34: 211334 | B34: AI policy (Franklin Clerk) | C34: No Responsive Documents | D34: no_docs | E34: Public | F34: 43745 | G34: Franklin Clerk | H34: Franklin | I34: 23852 | K34: 0 | L34: 2026-05-15 12:32 | M34: 2026-05-22 14:09 | N34: 2026-05-22 14:09 | O34: 6 | Q34: https://www.muckrock.com/foi/franklin-3874/ai-policy-franklin-clerk-211334/ | R34: transparent-nh | S34: Franklin | T34: town | U34: Franklin School District/SAU18 | V34: 0 | X34: =IF(Y34=TRUE,"",IF(ISNUMBER(W34),W34,V34)) | Y34: FALSE
A35: 200167 | B35: AI policy (Gorham Clerk) | C35: No Responsive Documents | D35: no_docs | E35: Public | F35: 43752 | G35: Gorham Clerk | H35: Gorham | I35: 114503 | K35: 0 | L35: 2025-12-18 16:38 | M35: 2025-12-24 13:38 | N35: 2025-12-24 13:38 | O35: 5 | Q35: https://www.muckrock.com/foi/gorham-3881/ai-policy-gorham-clerk-200167/ | R35: transparent-nh | S35: Gorham | T35: town | U35: Gorham School District/SAU20 | V35: 0 | X35: =IF(Y35=TRUE,"",IF(ISNUMBER(W35),W35,V35)) | Y35: FALSE
A36: 200168 | B36: AI policy (Hanover Clerk) | C36: No Responsive Documents | D36: no_docs | E36: Public | F36: 43751 | G36: Hanover Clerk | H36: Hanover | I36: 114503 | K36: 0 | L36: 2025-12-18 16:38 | M36: 2025-12-23 14:35 | N36: 2025-12-23 14:35 | O36: 4 | Q36: https://www.muckrock.com/foi/hanover-3893/ai-policy-hanover-clerk-200168/ | R36: transparent-nh | S36: Hanover | T36: town | U36: Interstate School District/SAU70 | V36: 0 | X36: =IF(Y36=TRUE,"",IF(ISNUMBER(W36),W36,V36)) | Y36: FALSE
A37: 200165 | B37: AI policy (Hopkinton Clerk) | C37: No Responsive Documents | D37: no_docs | E37: Public | F37: 43754 | G37: Hopkinton Clerk | H37: Hopkinton | I37: 114503 | K37: 0 | L37: 2025-12-18 16:38 | M37: 2025-12-31 16:23 | N37: 2025-12-31 16:23 | O37: 10 | Q37: https://www.muckrock.com/foi/hopkinton-3905/ai-policy-hopkinton-clerk-200165/ | R37: transparent-nh | S37: Hopkinton | T37: town | U37: Hopkinton School District/SAU66 | V37: 0 | X37: =IF(Y37=TRUE,"",IF(ISNUMBER(W37),W37,V37)) | Y37: FALSE
A38: 200155 | B38: AI policy (Laconia Clerk) | C38: No Responsive Documents | D38: no_docs | E38: Public | F38: 43746 | G38: Laconia Clerk | H38: Laconia | I38: 114503 | K38: 0 | L38: 2025-12-18 16:32 | M38: 2025-12-22 20:57 | N38: 2025-12-22 20:57 | O38: 3 | Q38: https://www.muckrock.com/foi/laconia-3913/ai-policy-laconia-clerk-200155/ | R38: transparent-nh | S38: Laconia | T38: town | U38: Laconia School District/SAU30 | V38: 0 | X38: =IF(Y38=TRUE,"",IF(ISNUMBER(W38),W38,V38)) | Y38: FALSE
A39: 200159 | B39: AI policy (Manchester City Clerk) | C39: Completed | D39: done | E39: Public | F39: 8901 | G39: Manchester City Clerk | H39: Manchester | I39: 114503 | K39: 0 | L39: 2025-12-18 16:32 | M39: 2025-12-22 13:45 | N39: 2025-12-22 13:45 | O39: 3 | Q39: https://www.muckrock.com/foi/manchester-3931/ai-policy-manchester-city-clerk-200159/ | R39: transparent-nh | S39: Manchester | T39: town | U39: Manchester School District/SAU37 | V39: 5 | X39: =IF(Y39=TRUE,"",IF(ISNUMBER(W39),W39,V39)) | Y39: FALSE
A40: 200153 | B40: AI policy (Nashua City Clerk) | C40: No Responsive Documents | D40: no_docs | E40: Public | F40: 11758 | G40: Nashua City Clerk | H40: Nashua | I40: 114503 | J40: 25-653 | K40: 0 | L40: 2025-12-18 16:32 | M40: 2025-12-30 13:15 | N40: 2025-12-30 13:15 | O40: 9 | Q40: https://www.muckrock.com/foi/nashua-3944/ai-policy-nashua-city-clerk-200153/ | R40: transparent-nh | S40: Nashua | T40: town | U40: Nashua School District/SAU 42 | V40: 0 | X40: =IF(Y40=TRUE,"",IF(ISNUMBER(W40),W40,V40)) | Y40: FALSE
...

Sheet Entities
A1: Entity | B1: Kind | C1: Counterpart | D1: Request Count | E1: Avg Score | F1: Summary | G1: Agency Response
A2: Belmont | B2: town | C2: Shaker Regional School District/SAU80 | D2: =COUNTIF(Requests!$S$2:$S$281,A2) | E2: =IFERROR(AVERAGEIFS(Requests!$X$2:$X$281,Requests!$S$2:$S$281,A2),"")
A3: Berlin | B3: town | C3: Berlin School District/SAU 3 | D3: =COUNTIF(Requests!$S$2:$S$281,A3) | E3: =IFERROR(AVERAGEIFS(Requests!$X$2:$X$281,Requests!$S$2:$S$281,A3),"")
A4: Bow | B4: town | C4: Bow School District/SAU67 | D4: =COUNTIF(Requests!$S$2:$S$281,A4) | E4: =IFERROR(AVERAGEIFS(Requests!$X$2:$X$281,Requests!$S$2:$S$281,A4),"")
A5: Claremont | B5: town | C5: Claremont School District/SAU6 | D5: =COUNTIF(Requests!$S$2:$S$281,A5) | E5: =IFERROR(AVERAGEIFS(Requests!$X$2:$X$281,Requests!$S$2:$S$281,A5),"")
A6: Concord | B6: town | C6: Concord School District/SAU8 | D6: =COUNTIF(Requests!$S$2:$S$281,A6) | E6: =IFERROR(AVERAGEIFS(Requests!$X$2:$X$281,Requests!$S$2:$S$281,A6),"")
A7: Derry | B7: town | C7: Derry Cooperative School District/SAU10 | D7: =COUNTIF(Requests!$S$2:$S$281,A7) | E7: =IFERROR(AVERAGEIFS(Requests!$X$2:$X$281,Requests!$S$2:$S$281,A7),"")
A8: Dover | B8: town | C8: Dover School District/SAU11 | D8: =COUNTIF(Requests!$S$2:$S$281,A8) | E8: =IFERROR(AVERAGEIFS(Requests!$X$2:$X$281,Requests!$S$2:$S$281,A8),"")
A9: Durham | B9: town | C9: Oyster River Cooperative School District/SAU5 | D9: =COUNTIF(Requests!$S$2:$S$281,A9) | E9: =IFERROR(AVERAGEIFS(Requests!$X$2:$X$281,Requests!$S$2:$S$281,A9),"")
A10: Franklin | B10: town | C10: Franklin School District/SAU18 | D10: =COUNTIF(Requests!$S$2:$S$281,A10) | E10: =IFERROR(AVERAGEIFS(Requests!$X$2:$X$281,Requests!$S$2:$S$281,A10),"")
A11: Gorham | B11: town | C11: Gorham School District/SAU20 | D11: =COUNTIF(Requests!$S$2:$S$281,A11) | E11: =IFERROR(AVERAGEIFS(Requests!$X$2:$X$281,Requests!$S$2:$S$281,A11),"")
A12: Hanover | B12: town | C12: Interstate School District/SAU70 | D12: =COUNTIF(Requests!$S$2:$S$281,A12) | E12: =IFERROR(AVERAGEIFS(Requests!$X$2:$X$281,Requests!$S$2:$S$281,A12),"")
A13: Hopkinton | B13: town | C13: Hopkinton School District/SAU66 | D13: =COUNTIF(Requests!$S$2:$S$281,A13) | E13: =IFERROR(AVERAGEIFS(Requests!$X$2:$X$281,Requests!$S$2:$S$281,A13),"")
... A47: Somersworth School District/SAU56 | B47: district | C47: Somersworth | D47: =COUNTIF(Requests!$S$2:$S$281,A47) | E47: =IFERROR(AVERAGEIFS(Requests!$X$2:$X$281,Requests!$S$2:$S$281,A47),"")
